Workbook

Sheet 2026
A1: DATA TENDIK FAKULTAS KEDOKTERAN UNPAD
A2: =TODAY() -> 46232 | C2: 2 | D2: 3 | E2: 7 | F2: 8 | G2: 9 | H2: 10 | I2: 11 | J2: 12 | K2: 13 | L2: 14 | M2: 24 | N2: 25 | O2: 26 | P2: 27 | Q2: 28 | R2: 29 | S2: 30 | T2: 31 | U2: 32 | V2: 33
A3: NO | B3: NIP | C3: NAMA | D3: STATUS | E3: JABATAN FUNGSIONAL | F3: TYPE | G3: TMT CPNS | H3: PANGKAT | I3: GOL. | J3: TMT PANGKAT | K3: MASA KERJA SK PANGKAT | L3: MASA KERJA PANGKAT | M3: JENIS KELAMIN | N3: TEMPAT TANGGAL LAHIR | O3: TANGGAL LAHIR | P3: NIK | Q3: NPWP | R3: USIA | U3: MASA KERJA | V3: PENSIUN
A4: 1 | B4: 197303192016023001 | C4: A. Wahyu, A.Md | D4: Non PNS | E4: Pengadministrasi Kepegawaian | F4: JF-NPNS | G4: 42401 | H4: =VLOOKUP(I4,Sheet1!$A$4:$B$20,2,0) -> Pengatur Tk. I (Gol. II/d) | I4: II/d | J4: 45566 | K4: 12 tahun 7 bulan | L4: =DATEDIF(J4,$A$2,"Y")&" tahun, "&DATEDIF(J4,$A$2,"YM")&" bulan" -> 1 tahun, 9 bulan | M4: Laki-Laki | N4: Bandung | O4: 26742 | P4: 3273111903730003 | Q4: 581507449424000 | R4: =DATEDIF(O4,$A$2,"Y")&" tahun" -> 53 tahun | S4: =DATEDIF(O4,$A$2,"YM")&" bulan" -> 4 bulan | T4: =DATEDIF(O4,$A$2,"MD")&" hari" -> 10 hari | U4: =DATEDIF(G4,$A$2,"Y")&" tahun, "&DATEDIF(G4,$A$2,"Ym")&" bulan" -> 10 tahun, 5 bulan | V4: =DATE(YEAR(O4)+58,MONTH(O4)+1,1) -> 47939
A5: 2 | B5: 197005112007011002 | C5: Aceng Nana, S.AP | D5: PNS | E5: Pustakawan Ahli Muda | F5: JFT | G5: 39083 | H5: =VLOOKUP(I5,Sheet1!$A$4:$B$20,2,0) -> Penata (Gol. III/c) | I5: III/c | J5: 46113 | K5: 26 tahun 0 bulan | L5: =DATEDIF(J5,$A$2,"Y")&" tahun, "&DATEDIF(J5,$A$2,"YM")&" bulan" -> 0 tahun, 3 bulan | M5: Laki-Laki | N5: Sumedang | O5: 25699 | P5: 3211151105700019 | Q5: 349332189446000 | R5: =DATEDIF(O5,$A$2,"Y")&" tahun" -> 56 tahun | S5: =DATEDIF(O5,$A$2,"YM")&" bulan" -> 2 bulan | T5: =DATEDIF(O5,$A$2,"MD")&" hari" -> 18 hari | U5: =DATEDIF(G5,$A$2,"Y")&" tahun, "&DATEDIF(G5,$A$2,"Ym")&" bulan" -> 19 tahun, 6 bulan | V5: =DATE(YEAR(O5)+58,MONTH(O5)+1,1) -> 46905
A6: 3 | B6: 197206302014091003 | C6: Achmad Qomarudin Shaleh | D6: PNS | E6: Pengadministrasi Keuangan | F6: JF | G6: 41883 | H6: =VLOOKUP(I6,Sheet1!$A$4:$B$20,2,0) -> Pengatur (Gol. II/c) | I6: II/c | J6: 44835 | K6: 18 tahun 6 bulan | L6: =DATEDIF(J6,$A$2,"Y")&" tahun, "&DATEDIF(J6,$A$2,"YM")&" bulan" -> 3 tahun, 9 bulan | M6: Laki-Laki | N6: Bandung | O6: 26480 | P6: 3273043006720001 | Q6: 970333753422000 | R6: =DATEDIF(O6,$A$2,"Y")&" tahun" -> 54 tahun | S6: =DATEDIF(O6,$A$2,"YM")&" bulan" -> 0 bulan | T6: =DATEDIF(O6,$A$2,"MD")&" hari" -> 29 hari | U6: =DATEDIF(G6,$A$2,"Y")&" tahun, "&DATEDIF(G6,$A$2,"Ym")&" bulan" -> 11 tahun, 10 bulan | V6: =DATE(YEAR(O6)+58,MONTH(O6)+1,1) -> 47665
A7: 4 | B7: 197212112007011001 | C7: Adang Junaedi | D7: PNS | E7: Pengemudi | F7: JF | G7: 39083 | H7: =VLOOKUP(I7,Sheet1!$A$4:$B$20,2,0) -> Pengatur Tk. I (Gol. II/d) | I7: II/d | J7: 45017 | L7: =DATEDIF(J7,$A$2,"Y")&" tahun, "&DATEDIF(J7,$A$2,"YM")&" bulan" -> 3 tahun, 3 bulan | M7: Laki-Laki | N7: Kadipaten | O7: 26644 | P7: 3211111112720006 | Q7: 586241630446000 | R7: =DATEDIF(O7,$A$2,"Y")&" tahun" -> 53 tahun | S7: =DATEDIF(O7,$A$2,"YM")&" bulan" -> 7 bulan | T7: =DATEDIF(O7,$A$2,"MD")&" hari" -> 18 hari | U7: =DATEDIF(G7,$A$2,"Y")&" tahun, "&DATEDIF(G7,$A$2,"Ym")&" bulan" -> 19 tahun, 6 bulan | V7: =DATE(YEAR(O7)+58,MONTH(O7)+1,1) -> 47849
A8: 5 | B8: 197309052007101001 | C8: Ade Komarudin, S.E | D8: PNS | E8: Pengadministrasi Akademik | F8: JF | G8: 39356 | H8: =VLOOKUP(I8,Sheet1!$A$4:$B$20,2,0) -> Penata Muda Tk.I (Gol. III/b) | I8: III/b | J8: 45748 | K8: 19 tahun 3 bulan | L8: =DATEDIF(J8,$A$2,"Y")&" tahun, "&DATEDIF(J8,$A$2,"YM")&" bulan" -> 1 tahun, 3 bulan | M8: Laki-Laki | N8: Bandung | O8: 26912 | P8: 3277010509730023 | Q8: 269697777421000 | R8: =DATEDIF(O8,$A$2,"Y")&" tahun" -> 52 tahun | S8: =DATEDIF(O8,$A$2,"YM")&" bulan" -> 10 bulan | T8: =DATEDIF(O8,$A$2,"MD")&" hari" -> 24 hari | U8: =DATEDIF(G8,$A$2,"Y")&" tahun, "&DATEDIF(G8,$A$2,"Ym")&" bulan" -> 18 tahun, 9 bulan | V8: =DATE(YEAR(O8)+58,MONTH(O8)+1,1) -> 48122
A9: 6 | B9: 197612122008101001 | C9: Ade Taryat | D9: PNS | E9: Pengadministrasi Akademik | F9: JF | G9: 39722 | H9: =VLOOKUP(I9,Sheet1!$A$4:$B$20,2,0) -> Penata Muda (Gol. III/a) | I9: III/a | J9: 45566 | K9: 19 tahun 6 bulan | L9: =DATEDIF(J9,$A$2,"Y")&" tahun, "&DATEDIF(J9,$A$2,"YM")&" bulan" -> 1 tahun, 9 bulan | M9: Laki-Laki | N9: Bandung | O9: 28106 | P9: 3273301212760002 | Q9: 586241622429000 | R9: =DATEDIF(O9,$A$2,"Y")&" tahun" -> 49 tahun | S9: =DATEDIF(O9,$A$2,"YM")&" bulan" -> 7 bulan | T9: =DATEDIF(O9,$A$2,"MD")&" hari" -> 17 hari | U9: =DATEDIF(G9,$A$2,"Y")&" tahun, "&DATEDIF(G9,$A$2,"Ym")&" bulan" -> 17 tahun, 9 bulan | V9: =DATE(YEAR(O9)+58,MONTH(O9)+1,1) -> 49310
A10: 7 | B10: 198509182016023001 | C10: Adhi Taufiq Akbar, S.T | D10: Non PNS | E10: Teknisi Terampil | F10: JF-NPNS | G10: 42401 | H10: =VLOOKUP(I10,Sheet1!$A$4:$B$20,2,0) -> Penata Muda Tk.I (Gol. III/b) | I10: III/b | J10: 45200 | L10: =DATEDIF(J10,$A$2,"Y")&" tahun, "&DATEDIF(J10,$A$2,"YM")&" bulan" -> 2 tahun, 9 bulan | M10: Laki-Laki | N10: Bandung | O10: 31308 | P10: 3273261809850001 | Q10: 461600082429000 | R10: =DATEDIF(O10,$A$2,"Y")&" tahun" -> 40 tahun | S10: =DATEDIF(O10,$A$2,"YM")&" bulan" -> 10 bulan | T10: =DATEDIF(O10,$A$2,"MD")&" hari" -> 11 hari | U10: =DATEDIF(G10,$A$2,"Y")&" tahun, "&DATEDIF(G10,$A$2,"Ym")&" bulan" -> 10 tahun, 5 bulan | V10: =DATE(YEAR(O10)+58,MONTH(O10)+1,1) -> 52505
A11: 8 | B11: 197908022007101001 | C11: Adi Supriadi | D11: PNS | E11: Teknisi Pelaksana | F11: JF | G11: 39356 | H11: =VLOOKUP(I11,Sheet1!$A$4:$B$20,2,0) -> Pengatur (Gol. II/c) | I11: II/c | J11: 45444 | L11: =DATEDIF(J11,$A$2,"Y")&" tahun, "&DATEDIF(J11,$A$2,"YM")&" bulan" -> 2 tahun, 1 bulan | M11: Laki-Laki | N11: Sumedang | O11: 29069 | P11: 3204050208790012 | Q11: 349262501446000 | R11: =DATEDIF(O11,$A$2,"Y")&" tahun" -> 46 tahun | S11: =DATEDIF(O11,$A$2,"YM")&" bulan" -> 11 bulan | T11: =DATEDIF(O11,$A$2,"MD")&" hari" -> 27 hari | U11: =DATEDIF(G11,$A$2,"Y")&" tahun, "&DATEDIF(G11,$A$2,"Ym")&" bulan" -> 18 tahun, 9 bulan | V11: =DATE(YEAR(O11)+58,MONTH(O11)+1,1) -> 50284
A12: 9 | B12: 198403272016023001 | C12: Adimyati | D12: Non PNS | E12: Pengadministrasi Akademik | F12: JF-NPNS | G12: 42401 | H12: =VLOOKUP(I12,Sheet1!$A$4:$B$20,2,0) -> Pengatur (Gol. II/c) | I12: II/c | J12: 45748 | K12: 15 tahun 0 bulan | L12: =DATEDIF(J12,$A$2,"Y")&" tahun, "&DATEDIF(J12,$A$2,"YM")&" bulan" -> 1 tahun, 3 bulan | M12: Laki-Laki | N12: Sumedang | O12: 30768 | P12: 3211112703840006 | Q12: 358358349446000 | R12: =DATEDIF(O12,$A$2,"Y")&" tahun" -> 42 tahun | S12: =DATEDIF(O12,$A$2,"YM")&" bulan" -> 4 bulan | T12: =DATEDIF(O12,$A$2,"MD")&" hari" -> 2 hari | U12: =DATEDIF(G12,$A$2,"Y")&" tahun, "&DATEDIF(G12,$A$2,"Ym")&" bulan" -> 10 tahun, 5 bulan | V12: =DATE(YEAR(O12)+58,MONTH(O12)+1,1) -> 51957
A13: 10 | B13: 197802232016023001 | C13: Ading | D13: Non PNS | E13: Pengadministrasi Akademik | F13: JF-NPNS | G13: 42401 | H13: =VLOOKUP(I13,Sheet1!$A$4:$B$20,2,0) -> Pengatur Muda Tk. I (Gol. II/b) | I13: II/b | J13: 44835 | L13: =DATEDIF(J13,$A$2,"Y")&" tahun, "&DATEDIF(J13,$A$2,"YM")&" bulan" -> 3 tahun, 9 bulan | M13: Laki-Laki | N13: Sumedang | O13: 28544 | P13: 3211152302780004 | Q13: 770124121446000 | R13: =DATEDIF(O13,$A$2,"Y")&" tahun" -> 48 tahun | S13: =DATEDIF(O13,$A$2,"YM")&" bulan" -> 5 bulan | T13: =DATEDIF(O13,$A$2,"MD")&" hari" -> 6 hari | U13: =DATEDIF(G13,$A$2,"Y")&" tahun, "&DATEDIF(G13,$A$2,"Ym")&" bulan" -> 10 tahun, 5 bulan | V13: =DATE(YEAR(O13)+58,MONTH(O13)+1,1) -> 49735
A14: 11 | B14: 197507192019063001 | C14: Aep Hidayat | D14: Non PNS | E14: Pramu | F14: JF-NPNS | G14: 43617 | H14: =VLOOKUP(I14,Sheet1!$A$4:$B$20,2,0) -> Pengatur (Gol. II/c) | I14: II/c | J14: 45748 | K14: 5 tahun 10 bulan | L14: =DATEDIF(J14,$A$2,"Y")&" tahun, "&DATEDIF(J14,$A$2,"YM")&" bulan" -> 1 tahun, 3 bulan | M14: Laki-Laki | N14: Bandung | O14: 27594 | P14: 3217061907750011 | Q14: 358472132421000 | R14: =DATEDIF(O14,$A$2,"Y")&" tahun" -> 51 tahun | S14: =DATEDIF(O14,$A$2,"YM")&" bulan" -> 0 bulan | T14: =DATEDIF(O14,$A$2,"MD")&" hari" -> 10 hari | U14: =DATEDIF(G14,$A$2,"Y")&" tahun, "&DATEDIF(G14,$A$2,"Ym")&" bulan" -> 7 tahun, 1 bulan | V14: =DATE(YEAR(O14)+58,MONTH(O14)+1,1) -> 48792
A15: 12 | B15: 197708292009101001 | C15: Agus Saepul | D15: PNS | E15: Teknisi Pelaksana | F15: JF | G15: 40087 | H15: =VLOOKUP(I15,Sheet1!$A$4:$B$20,2,0) -> Penata Muda (Gol. III/a) | I15: III/a | J15: 45931 | K15: 18 tahun 8 bulan | L15: =DATEDIF(J15,$A$2,"Y")&" tahun, "&DATEDIF(J15,$A$2,"YM")&" bulan" -> 0 tahun, 9 bulan | M15: Laki-Laki | N15: Bandung | O15: 28366 | P15: 3273072908770004 | Q15: 880437215428000 | R15: =DATEDIF(O15,$A$2,"Y")&" tahun" -> 48 tahun | S15: =DATEDIF(O15,$A$2,"YM")&" bulan" -> 11 bulan | T15: =DATEDIF(O15,$A$2,"MD")&" hari" -> 0 hari | U15: =DATEDIF(G15,$A$2,"Y")&" tahun, "&DATEDIF(G15,$A$2,"Ym")&" bulan" -> 16 tahun, 9 bulan | V15: =DATE(YEAR(O15)+58,MONTH(O15)+1,1) -> 49553
A16: 13 | B16: 197705262016023001 | C16: Agus Sukarsah | D16: Non PNS | E16: Pengadministrasi Sarana dan Prasarana | F16: JF-NPNS | G16: 42401 | H16: =VLOOKUP(I16,Sheet1!$A$4:$B$20,2,0) -> Pengatur (Gol. II/c) | I16: II/c | J16: 45748 | K16: 12 tahun 2 bulan | L16: =DATEDIF(J16,$A$2,"Y")&" tahun, "&DATEDIF(J16,$A$2,"YM")&" bulan" -> 1 tahun, 3 bulan | M16: Laki-Laki | N16: Sumedang | O16: 28271 | P16: 3206362605770001 | Q16: 701397507425000 | R16: =DATEDIF(O16,$A$2,"Y")&" tahun" -> 49 tahun | S16: =DATEDIF(O16,$A$2,"YM")&" bulan" -> 2 bulan | T16: =DATEDIF(O16,$A$2,"MD")&" hari" -> 3 hari | U16: =DATEDIF(G16,$A$2,"Y")&" tahun, "&DATEDIF(G16,$A$2,"Ym")&" bulan" -> 10 tahun, 5 bulan | V16: =DATE(YEAR(O16)+58,MONTH(O16)+1,1) -> 49461
A17: 14 | B17: 198508022009101001 | C17: Agus Supriatna, S.Sos. | D17: PNS | E17: Pengadministrasi Akademik | F17: JF | G17: 40087 | H17: =VLOOKUP(I17,Sheet1!$A$4:$B$20,2,0) -> Penata (Gol. III/c) | I17: III/c | J17: 45383 | K17: 15 tahun 3 bulan | L17: =DATEDIF(J17,$A$2,"Y")&" tahun, "&DATEDIF(J17,$A$2,"YM")&" bulan" -> 2 tahun, 3 bulan | M17: Laki-Laki | N17: Bandung | O17: 31261 | P17: 3273010208850001 | Q17: 842934770429000 | R17: =DATEDIF(O17,$A$2,"Y")&" tahun" -> 40 tahun | S17: =DATEDIF(O17,$A$2,"YM")&" bulan" -> 11 bulan | T17: =DATEDIF(O17,$A$2,"MD")&" hari" -> 27 hari | U17: =DATEDIF(G17,$A$2,"Y")&" tahun, "&DATEDIF(G17,$A$2,"Ym")&" bulan" -> 16 tahun, 9 bulan | V17: =DATE(YEAR(O17)+58,MONTH(O17)+1,1) -> 52475
A18: 15 | B18: 197903252014091001 | C18: Ahdiat Kurniawan | D18: PNS | E18: Pengadministrasi Sarana dan Prasarana | F18: JF | G18: 41883 | H18: =VLOOKUP(I18,Sheet1!$A$4:$B$20,2,0) -> Pengatur (Gol. II/c) | I18: II/c | J18: 44835 | L18: =DATEDIF(J18,$A$2,"Y")&" tahun, "&DATEDIF(J18,$A$2,"YM")&" bulan" -> 3 tahun, 9 bulan | M18: Laki-Laki | N18: Sumedang | O18: 28939 | P18: 3211152503790001 | Q18: 358458123446000 | R18: =DATEDIF(O18,$A$2,"Y")&" tahun" -> 47 tahun | S18: =DATEDIF(O18,$A$2,"YM")&" bulan" -> 4 bulan | T18: =DATEDIF(O18,$A$2,"MD")&" hari" -> 4 hari | U18: =DATEDIF(G18,$A$2,"Y")&" tahun, "&DATEDIF(G18,$A$2,"Ym")&" bulan" -> 11 tahun, 10 bulan | V18: =DATE(YEAR(O18)+58,MONTH(O18)+1,1) -> 50131
A19: 16 | B19: 197610082007011001 | C19: Ahmad | D19: PNS | E19: Pengelola Pengadaan Barang dan Jasa | F19: JF | G19: 39083 | H19: =VLOOKUP(I19,Sheet1!$A$4:$B$20,2,0) -> Penata Muda (Gol. III/a) | I19: III/a | J19: 45017 | L19: =DATEDIF(J19,$A$2,"Y")&" tahun, "&DATEDIF(J19,$A$2,"YM")&" bulan" -> 3 tahun, 3 bulan | M19: Laki-Laki | N19: Bandung | O19: 28041 | P19: 3204280810760003 | Q19: 352333272444000 | R19: =DATEDIF(O19,$A$2,"Y")&" tahun" -> 49 tahun | S19: =DATEDIF(O19,$A$2,"YM")&" bulan" -> 9 bulan | T19: =DATEDIF(O19,$A$2,"MD")&" hari" -> 21 hari | U19: =DATEDIF(G19,$A$2,"Y")&" tahun, "&DATEDIF(G19,$A$2,"Ym")&" bulan" -> 19 tahun, 6 bulan | V19: =DATE(YEAR(O19)+58,MONTH(O19)+1,1) -> 49249
A20: 17 | B20: 197708202016023001 | C20: Ajat Sudrajat, S.E | D20: Non PNS | E20: Pengelola Kepegawaian | F20: JF-NPNS | G20: 42401 | H20: =VLOOKUP(I20,Sheet1!$A$4:$B$20,2,0) -> Penata Muda Tk.I (Gol. III/b) | I20: III/b | J20: 45017 | L20: =DATEDIF(J20,$A$2,"Y")&" tahun, "&DATEDIF(J20,$A$2,"YM")&" bulan" -> 3 tahun, 3 bulan | M20: Laki-Laki | N20: Kuningan | O20: 28357 | P20: 3273222008770003 | Q20: 358325538429000 | R20: =DATEDIF(O20,$A$2,"Y")&" tahun" -> 48 tahun | S20: =DATEDIF(O20,$A$2,"YM")&" bulan" -> 11 bulan | T20: =DATEDIF(O20,$A$2,"MD")&" hari" -> 9 hari | U20: =DATEDIF(G20,$A$2,"Y")&" tahun, "&DATEDIF(G20,$A$2,"Ym")&" bulan" -> 10 tahun, 5 bulan | V20: =DATE(YEAR(O20)+58,MONTH(O20)+1,1) -> 49553
A21: 18 | B21: 197601012014091003 | C21: Akin Mutakin, A.MK | D21: PNS | E21: Pranata Laboratorium Pendidikan Terampil | F21: JFT | G21: 41883 | H21: =VLOOKUP(I21,Sheet1!$A$4:$B$20,2,0) -> Pengatur Tk. I (Gol. II/d) | I21: II/d | J21: 45627 | L21: =DATEDIF(J21,$A$2,"Y")&" tahun, "&DATEDIF(J21,$A$2,"YM")&" bulan" -> 1 tahun, 7 bulan | M21: Laki-Laki | N21: Tasikmalaya | O21: 27760 | P21: 3204330101760181 | Q21: 358818656444000 | R21: =DATEDIF(O21,$A$2,"Y")&" tahun" -> 50 tahun | S21: =DATEDIF(O21,$A$2,"YM")&" bulan" -> 6 bulan | T21: =DATEDIF(O21,$A$2,"MD")&" hari" -> 28 hari | U21: =DATEDIF(G21,$A$2,"Y")&" tahun, "&DATEDIF(G21,$A$2,"Ym")&" bulan" -> 11 tahun, 10 bulan | V21: =DATE(YEAR(O21)+58,MONTH(O21)+1,1) -> 48976
A22: 19 | B22: 196905181999031001 | C22: Amas Sutardi, A.Md. | D22: PNS | E22: Arsiparis Mahir | F22: JFT | G22: 36220 | H22: =VLOOKUP(I22,Sheet1!$A$4:$B$20,2,0) -> Penata Muda (Gol. III/a) | I22: III/a | J22: 42095 | L22: =DATEDIF(J22,$A$2,"Y")&" tahun, "&DATEDIF(J22,$A$2,"YM")&" bulan" -> 11 tahun, 3 bulan | M22: Laki-Laki | N22: Bandung | O22: 25341 | P22: 3211111805690001 | Q22: 349289355446000 | R22: =DATEDIF(O22,$A$2,"Y")&" tahun" -> 57 tahun | S22: =DATEDIF(O22,$A$2,"YM")&" bulan" -> 2 bulan | T22: =DATEDIF(O22,$A$2,"MD")&" hari" -> 11 hari | U22: =DATEDIF(G22,$A$2,"Y")&" tahun, "&DATEDIF(G22,$A$2,"Ym")&" bulan" -> 27 tahun, 4 bulan | V22: =DATE(YEAR(O22)+58,MONTH(O22)+1,1) -> 46539
A23: 20 | B23: 198009302014091002 | C23: Andi Darmawan, A.Md | D23: PNS | E23: Arsiparis Terampil | F23: JFT | G23: 41883 | H23: =VLOOKUP(I23,Sheet1!$A$4:$B$20,2,0) -> Pengatur Tk. I (Gol. II/d) | I23: II/d | J23: 43374 | L23: =DATEDIF(J23,$A$2,"Y")&" tahun, "&DATEDIF(J23,$A$2,"YM")&" bulan" -> 7 tahun, 9 bulan | M23: Laki-Laki | N23: Bandung | O23: 29494 | P23: 3273053009800002 | Q23: 358589224444000 | R23: =DATEDIF(O23,$A$2,"Y")&" tahun" -> 45 tahun | S23: =DATEDIF(O23,$A$2,"YM")&" bulan" -> 9 bulan | T23: =DATEDIF(O23,$A$2,"MD")&" hari" -> 29 hari | U23: =DATEDIF(G23,$A$2,"Y")&" tahun, "&DATEDIF(G23,$A$2,"Ym")&" bulan" -> 11 tahun, 10 bulan | V23: =DATE(YEAR(O23)+58,MONTH(O23)+1,1) -> 50679
A24: 21 | B24: 197708292016024001 | C24: Anggreani Selyafitri, SE.Ak | D24: Non PNS | E24: Pengadministrasi Kepegawaian | F24: JF-NPNS | G24: 42401 | H24: =VLOOKUP(I24,Sheet1!$A$4:$B$20,2,0) -> Penata Muda Tk.I (Gol. III/b) | I24: III/b | J24: 44835 | L24: =DATEDIF(J24,$A$2,"Y")&" tahun, "&DATEDIF(J24,$A$2,"YM")&" bulan" -> 3 tahun, 9 bulan | M24: Perempuan | N24: Bandung | O24: 28366 | P24: 3277026908770012 | Q24: 358403038421000 | R24: =DATEDIF(O24,$A$2,"Y")&" tahun" -> 48 tahun | S24: =DATEDIF(O24,$A$2,"YM")&" bulan" -> 11 bulan | T24: =DATEDIF(O24,$A$2,"MD")&" hari" -> 0 hari | U24: =DATEDIF(G24,$A$2,"Y")&" tahun, "&DATEDIF(G24,$A$2,"Ym")&" bulan" -> 10 tahun, 5 bulan | V24: =DATE(YEAR(O24)+58,MONTH(O24)+1,1) -> 49553
A25: 22 | B25: 197401101994032001 | C25: Ani Raniati | D25: PNS | E25: Pranata Laboratorium Pendidikan Mahir | F25: JFT | G25: 34394 | H25: =VLOOKUP(I25,Sheet1!$A$4:$B$20,2,0) -> Penata Muda Tk.I (Gol. III/b) | I25: III/b | J25: 42826 | L25: =DATEDIF(J25,$A$2,"Y")&" tahun, "&DATEDIF(J25,$A$2,"YM")&" bulan" -> 9 tahun, 3 bulan | M25: Perempuan | N25: Bandung | O25: 27039 | P25: 3273025001740016 | Q25: 349310946446000 | R25: =DATEDIF(O25,$A$2,"Y")&" tahun" -> 52 tahun | S25: =DATEDIF(O25,$A$2,"YM")&" bulan" -> 6 bulan | T25: =DATEDIF(O25,$A$2,"MD")&" hari" -> 19 hari | U25: =DATEDIF(G25,$A$2,"Y")&" tahun, "&DATEDIF(G25,$A$2,"Ym")&" bulan" -> 32 tahun, 4 bulan | V25: =DATE(YEAR(O25)+58,MONTH(O25)+1,1) -> 48245
A26: 23 | B26: 197307082008102001 | C26: Anna Yulia, SH | D26: PNS | E26: Arsiparis Ahli Muda | F26: JFT | G26: 39722 | H26: =VLOOKUP(I26,Sheet1!$A$4:$B$20,2,0) -> Penata Tk.I (Gol. III/d) | I26: III/d | J26: 44835 | L26: =DATEDIF(J26,$A$2,"Y")&" tahun, "&DATEDIF(J26,$A$2,"YM")&" bulan" -> 3 tahun, 9 bulan | M26: Perempuan | N26: Bandung | O26: 26853 | P26: 3273174807730003 | Q26: 580398840422000 | R26: =DATEDIF(O26,$A$2,"Y")&" tahun" -> 53 tahun | S26: =DATEDIF(O26,$A$2,"YM")&" bulan" -> 0 bulan | T26: =DATEDIF(O26,$A$2,"MD")&" hari" -> 21 hari | U26: =DATEDIF(G26,$A$2,"Y")&" tahun, "&DATEDIF(G26,$A$2,"Ym")&" bulan" -> 17 tahun, 9 bulan | V26: =DATE(YEAR(O26)+58,MONTH(O26)+1,1) -> 48061
A27: 24 | B27: 198308122009101001 | C27: Anton Soejarwo | D27: PNS | E27: Pengadministrasi Kepegawaian | F27: JF | G27: 40087 | H27: =VLOOKUP(I27,Sheet1!$A$4:$B$20,2,0) -> Pengatur Tk. I (Gol. II/d) | I27: II/d | J27: 45017 | L27: =DATEDIF(J27,$A$2,"Y")&" tahun, "&DATEDIF(J27,$A$2,"YM")&" bulan" -> 3 tahun, 3 bulan | M27: Laki-Laki | N27: Medan | O27: 30540 | P27: 3204281208830001 | Q27: 349345710444000 | R27: =DATEDIF(O27,$A$2,"Y")&" tahun" -> 42 tahun | S27: =DATEDIF(O27,$A$2,"YM")&" bulan" -> 11 bulan | T27: =DATEDIF(O27,$A$2,"MD")&" hari" -> 17 hari | U27: =DATEDIF(G27,$A$2,"Y")&" tahun, "&DATEDIF(G27,$A$2,"Ym")&" bulan" -> 16 tahun, 9 bulan | V27: =DATE(YEAR(O27)+58,MONTH(O27)+1,1) -> 51745
A28: 25 | B28: 198312292014091001 | C28: Argie Rizki Maulana | D28: PNS | E28: Pengelola Data Akademik | F28: JF | G28: 41883 | H28: =VLOOKUP(I28,Sheet1!$A$4:$B$20,2,0) -> Pengatur (Gol. II/c) | I28: II/c | J28: 44835 | L28: =DATEDIF(J28,$A$2,"Y")&" tahun, "&DATEDIF(J28,$A$2,"YM")&" bulan" -> 3 tahun, 9 bulan | M28: Laki-Laki | N28: Bandung | O28: 30679 | P28: 3204052912830015 | Q28: 358625705423000 | R28: =DATEDIF(O28,$A$2,"Y")&" tahun" -> 42 tahun | S28: =DATEDIF(O28,$A$2,"YM")&" bulan" -> 7 bulan | T28: =DATEDIF(O28,$A$2,"MD")&" hari" -> 0 hari | U28: =DATEDIF(G28,$A$2,"Y")&" tahun, "&DATEDIF(G28,$A$2,"Ym")&" bulan" -> 11 tahun, 10 bulan | V28: =DATE(YEAR(O28)+58,MONTH(O28)+1,1) -> 51867
A29: 26 | B29: 198003152009101001 | C29: Ari Darmawan | D29: PNS | E29: Pengadministrasi | F29: JF | G29: 40087 | H29: =VLOOKUP(I29,Sheet1!$A$4:$B$20,2,0) -> Pengatur Tk. I (Gol. II/d) | I29: II/d | J29: 45017 | L29: =DATEDIF(J29,$A$2,"Y")&" tahun, "&DATEDIF(J29,$A$2,"YM")&" bulan" -> 3 tahun, 3 bulan | M29: Laki-Laki | N29: Bandung | O29: 29295 | P29: 3273071503800002 | Q29: 349037523428000 | R29: =DATEDIF(O29,$A$2,"Y")&" tahun" -> 46 tahun | S29: =DATEDIF(O29,$A$2,"YM")&" bulan" -> 4 bulan | T29: =DATEDIF(O29,$A$2,"MD")&" hari" -> 14 hari | U29: =DATEDIF(G29,$A$2,"Y")&" tahun, "&DATEDIF(G29,$A$2,"Ym")&" bulan" -> 16 tahun, 9 bulan | V29: =DATE(YEAR(O29)+58,MONTH(O29)+1,1) -> 50496
A30: 27 | B30: 197104192014091001 | C30: Aries Budi Suharto | D30: PNS | E30: Teknisi Pelaksana | F30: JF | G30: 41883 | H30: =VLOOKUP(I30,Sheet1!$A$4:$B$20,2,0) -> Pengatur (Gol. II/c) | I30: II/c | J30: 44835 | L30: =DATEDIF(J30,$A$2,"Y")&" tahun, "&DATEDIF(J30,$A$2,"YM")&" bulan" -> 3 tahun, 9 bulan | M30: Laki-Laki | N30: Indramayu | O30: 26042 | P30: 3204081904710002 | Q30: 358863090444000 | R30: =DATEDIF(O30,$A$2,"Y")&" tahun" -> 55 tahun | S30: =DATEDIF(O30,$A$2,"YM")&" bulan" -> 3 bulan | T30: =DATEDIF(O30,$A$2,"MD")&" hari" -> 10 hari | U30: =DATEDIF(G30,$A$2,"Y")&" tahun, "&DATEDIF(G30,$A$2,"Ym")&" bulan" -> 11 tahun, 10 bulan | V30: =DATE(YEAR(O30)+58,MONTH(O30)+1,1) -> 47239
A31: 28 | B31: 197008122007011002 | C31: Asep Harmaen | D31: PNS | E31: Teknisi Pelaksana | F31: JF | G31: 39083 | H31: =VLOOKUP(I31,Sheet1!$A$4:$B$20,2,0) -> Penata Muda (Gol. III/a) | I31: III/a | J31: 46054 | K31: 25 tahun 5 bulan | L31: =DATEDIF(J31,$A$2,"Y")&" tahun, "&DATEDIF(J31,$A$2,"YM")&" bulan" -> 0 tahun, 5 bulan | M31: Laki-Laki | N31: Bandung | O31: 25792 | P31: 3273021208700003 | Q31: 796295970423000 | R31: =DATEDIF(O31,$A$2,"Y")&" tahun" -> 55 tahun | S31: =DATEDIF(O31,$A$2,"YM")&" bulan" -> 11 bulan | T31: =DATEDIF(O31,$A$2,"MD")&" hari" -> 17 hari | U31: =DATEDIF(G31,$A$2,"Y")&" tahun, "&DATEDIF(G31,$A$2,"Ym")&" bulan" -> 19 tahun, 6 bulan | V31: =DATE(YEAR(O31)+58,MONTH(O31)+1,1) -> 46997
A32: 29 | B32: 196912042009101001 | C32: Asep Koswara | D32: PNS | E32: Pengadministrasi Keuangan | F32: JF | G32: 40087 | H32: =VLOOKUP(I32,Sheet1!$A$4:$B$20,2,0) -> Penata Muda (Gol. III/a) | I32: III/a | J32: 45931 | K32: 18 tahun 8 bulan | L32: =DATEDIF(J32,$A$2,"Y")&" tahun, "&DATEDIF(J32,$A$2,"YM")&" bulan" -> 0 tahun, 9 bulan | M32: Laki-Laki | N32: Bandung | O32: 25541 | P32: 3204280412690002 | Q32: 818192452444000 | R32: =DATEDIF(O32,$A$2,"Y")&" tahun" -> 56 tahun | S32: =DATEDIF(O32,$A$2,"YM")&" bulan" -> 7 bulan | T32: =DATEDIF(O32,$A$2,"MD")&" hari" -> 25 hari | U32: =DATEDIF(G32,$A$2,"Y")&" tahun, "&DATEDIF(G32,$A$2,"Ym")&" bulan" -> 16 tahun, 9 bulan | V32: =DATE(YEAR(O32)+58,MONTH(O32)+1,1) -> 46753
A33: 30 | B33: 198004132008101001 | C33: Asep Kurnia, S.AP | D33: PNS | E33: Koordinator Bidang Akademik dan Kemahasiswaan | F33: JF | G33: 39722 | H33: =VLOOKUP(I33,Sheet1!$A$4:$B$20,2,0) -> Penata (Gol. III/c) | I33: III/c | J33: 46174 | K33: 22 tahun 1 bulan | L33: =DATEDIF(J33,$A$2,"Y")&" tahun, "&DATEDIF(J33,$A$2,"YM")&" bulan" -> 0 tahun, 1 bulan | M33: Laki-Laki | N33: Bandung | O33: 29324 | P33: 3273071304800001 | Q33: 265181438428000 | R33: =DATEDIF(O33,$A$2,"Y")&" tahun" -> 46 tahun | S33: =DATEDIF(O33,$A$2,"YM")&" bulan" -> 3 bulan | T33: =DATEDIF(O33,$A$2,"MD")&" hari" -> 16 hari | U33: =DATEDIF(G33,$A$2,"Y")&" tahun, "&DATEDIF(G33,$A$2,"Ym")&" bulan" -> 17 tahun, 9 bulan | V33: =DATE(YEAR(O33)+58,MONTH(O33)+1,1) -> 50526
A34: 31 | B34: 197401082007101002 | C34: Asep Najar Husnika | D34: PNS | E34: Teknisi Pelaksana | F34: JF | G34: 39356 | H34: =VLOOKUP(I34,Sheet1!$A$4:$B$20,2,0) -> Penata Muda (Gol. III/a) | I34: III/a | J34: 45566 | K34: 18 tahun 9 bulan | L34: =DATEDIF(J34,$A$2,"Y")&" tahun, "&DATEDIF(J34,$A$2,"YM")&" bulan" -> 1 tahun, 9 bulan | M34: Laki-Laki | N34: Ciililin | O34: 27037 | P34: 3211150801740004 | Q34: 349334649446000 | R34: =DATEDIF(O34,$A$2,"Y")&" tahun" -> 52 tahun | S34: =DATEDIF(O34,$A$2,"YM")&" bulan" -> 6 bulan | T34: =DATEDIF(O34,$A$2,"MD")&" hari" -> 21 hari | U34: =DATEDIF(G34,$A$2,"Y")&" tahun, "&DATEDIF(G34,$A$2,"Ym")&" bulan" -> 18 tahun, 9 bulan | V34: =DATE(YEAR(O34)+58,MONTH(O34)+1,1) -> 48245
A35: 32 | B35: 198708082016024001 | C35: Atu Purnama Dewi, S.Si | D35: Non PNS | E35: Pranata Laboratorium Pendidikan Ahli Pertama | F35: JFT-NPNS | G35: 42401 | H35: =VLOOKUP(I35,Sheet1!$A$4:$B$20,2,0) -> Penata Muda Tk.I (Gol. III/b) | I35: III/b | J35: 46113 | K35: 8 tahun 3 bulan | L35: =DATEDIF(J35,$A$2,"Y")&" tahun, "&DATEDIF(J35,$A$2,"YM")&" bulan" -> 0 tahun, 3 bulan | M35: Perempuan | N35: Bandung | O35: 31997 | P35: 3277014808870029 | Q35: 454318403421000 | R35: =DATEDIF(O35,$A$2,"Y")&" tahun" -> 38 tahun | S35: =DATEDIF(O35,$A$2,"YM")&" bulan" -> 11 bulan | T35: =DATEDIF(O35,$A$2,"MD")&" hari" -> 21 hari | U35: =DATEDIF(G35,$A$2,"Y")&" tahun, "&DATEDIF(G35,$A$2,"Ym")&" bulan" -> 10 tahun, 5 bulan | V35: =DATE(YEAR(O35)+58,MONTH(O35)+1,1) -> 53206
A36: 33 | B36: 197803162009102001 | C36: Ayi Nurdaliah Yusuf, A.Md | D36: PNS | E36: Pengadministrasi Kepegawaian | F36: JF | G36: 40087 | H36: =VLOOKUP(I36,Sheet1!$A$4:$B$20,2,0) -> Penata Muda Tk.I (Gol. III/b) | I36: III/b | J36: 45017 | K36: 19 tahun 2 bulan | L36: =DATEDIF(J36,$A$2,"Y")&" tahun, "&DATEDIF(J36,$A$2,"YM")&" bulan" -> 3 tahun, 3 bulan | M36: Perempuan | N36: Tasikmalaya | O36: 28565 | P36: 3204285603780006 | Q36: 347651978444999 | R36: =DATEDIF(O36,$A$2,"Y")&" tahun" -> 48 tahun | S36: =DATEDIF(O36,$A$2,"YM")&" bulan" -> 4 bulan | T36: =DATEDIF(O36,$A$2,"MD")&" hari" -> 13 hari | U36: =DATEDIF(G36,$A$2,"Y")&" tahun, "&DATEDIF(G36,$A$2,"Ym")&" bulan" -> 16 tahun, 9 bulan | V36: =DATE(YEAR(O36)+58,MONTH(O36)+1,1) -> 49766
A37: 34 | B37: 197309222007011001 | C37: Ayi Ratno Permana | D37: PNS | E37: Teknisi Pelaksana | F37: JF | G37: 39083 | H37: =VLOOKUP(I37,Sheet1!$A$4:$B$20,2,0) -> Pengatur Tk. I (Gol. II/d) | I37: II/d | J37: 46174 | K37: 26 tahun 7 bulan | L37: =DATEDIF(J37,$A$2,"Y")&" tahun, "&DATEDIF(J37,$A$2,"YM")&" bulan" -> 0 tahun, 1 bulan | M37: Laki-Laki | N37: Sumedang | O37: 26929 | P37: 3273072209730001 | Q37: 349372367428000 | R37: =DATEDIF(O37,$A$2,"Y")&" tahun" -> 52 tahun | S37: =DATEDIF(O37,$A$2,"YM")&" bulan" -> 10 bulan | T37: =DATEDIF(O37,$A$2,"MD")&" hari" -> 7 hari | U37: =DATEDIF(G37,$A$2,"Y")&" tahun, "&DATEDIF(G37,$A$2,"Ym")&" bulan" -> 19 tahun, 6 bulan | V37: =DATE(YEAR(O37)+58,MONTH(O37)+1,1) -> 48122
A38: 35 | B38: 200012272024084001 | C38: Ayu Prasasti Cahya Fitria, A.Md. | D38: Non PNS | E38: Pranata Laboratorium Pendidikan Terampil | F38: JFT-NPNS | G38: 45505 | H38: =VLOOKUP(I38,Sheet1!$A$4:$B$20,2,0) -> Pengatur (Gol. II/c) | I38: II/c | J38: 01 Agustus 2024 | L38: =DATEDIF(J38,$A$2,"Y")&" tahun, "&DATEDIF(J38,$A$2,"YM")&" bulan" -> 1 tahun, 11 bulan | M38: Perempuan | N38: Wonodadi | O38: 36887 | P38: 1810016812000005 | R38: =DATEDIF(O38,$A$2,"Y")&" tahun" -> 25 tahun | S38: =DATEDIF(O38,$A$2,"YM")&" bulan" -> 7 bulan | T38: =DATEDIF(O38,$A$2,"MD")&" hari" -> 2 hari | U38: =DATEDIF(G38,$A$2,"Y")&" tahun, "&DATEDIF(G38,$A$2,"Ym")&" bulan" -> 1 tahun, 11 bulan | V38: =DATE(YEAR(O38)+58,MONTH(O38)+1,1) -> 58076
A39: 36 | B39: 197602242016023001 | C39: Beben Ii Somantri | D39: Non PNS | E39: Pengadministrasi Sarana dan Prasarana | F39: JF-NPNS | G39: 42401 | H39: =VLOOKUP(I39,Sheet1!$A$4:$B$20,2,0) -> Pengatur (Gol. II/c) | I39: II/c | J39: 45748 | K39: 12 tahun 5 bulan | L39: =DATEDIF(J39,$A$2,"Y")&" tahun, "&DATEDIF(J39,$A$2,"YM")&" bulan" -> 1 tahun, 3 bulan | M39: Laki-Laki | N39: Bandung | O39: 27814 | P39: 3273022402760012 | Q39: 665576559423000 | R39: =DATEDIF(O39,$A$2,"Y")&" tahun" -> 50 tahun | S39: =DATEDIF(O39,$A$2,"YM")&" bulan" -> 5 bulan | T39: =DATEDIF(O39,$A$2,"MD")&" hari" -> 5 hari | U39: =DATEDIF(G39,$A$2,"Y")&" tahun, "&DATEDIF(G39,$A$2,"Ym")&" bulan" -> 10 tahun, 5 bulan | V39: =DATE(YEAR(O39)+58,MONTH(O39)+1,1) -> 49004
A40: 37 | B40: 200010162024083001 | C40: Bima Ali Akbar, A.Md. | D40: Non PNS | E40: Pranata Laboratorium Pendidikan Terampil | F40: JFT-NPNS | G40: 45505 | H40: =VLOOKUP(I40,Sheet1!$A$4:$B$20,2,0) -> Pengatur (Gol. II/c) | I40: II/c | J40: 01 Agustus 2024 | L40: =DATEDIF(J40,$A$2,"Y")&" tahun, "&DATEDIF(J40,$A$2,"YM")&" bulan" -> 1 tahun, 11 bulan | M40: Laki-Laki | N40: Magelang | O40: 36815 | P40: 3308091610000003 | R40: =DATEDIF(O40,$A$2,"Y")&" tahun" -> 25 tahun | S40: =DATEDIF(O40,$A$2,"YM")&" bulan" -> 9 bulan | T40: =DATEDIF(O40,$A$2,"MD")&" hari" -> 13 hari | U40: =DATEDIF(G40,$A$2,"Y")&" tahun, "&DATEDIF(G40,$A$2,"Ym")&" bulan" -> 1 tahun, 11 bulan | V40: =DATE(YEAR(O40)+58,MONTH(O40)+1,1) -> 58015
...

Sheet Sheet1
A1: PANGKAT DAN GOLONGAN
A3: GOL. | B3: PANGKAT | C3: JABATAN
A4: I/a | B4: Juru Muda | C4: -
A5: I/b | B5: Juru Muda Tk. I | C5: -
A6: I/c | B6: Juru (Gol. I/c) | C6: -
A7: I/d | B7: Juru Tk. I (Gol. I/d) | C7: -
A8: II/a | B8: Pengatur Muda (Gol. II/a) | C8: -
A9: II/b | B9: Pengatur Muda Tk. I (Gol. II/b) | C9: -
A10: II/c | B10: Pengatur (Gol. II/c) | C10: -
A11: II/d | B11: Pengatur Tk. I (Gol. II/d) | C11: -
A12: III/a | B12: Penata Muda (Gol. III/a) | C12: Asisten Ahli
A13: III/b | B13: Penata Muda Tk.I (Gol. III/b)
A14: III/c | B14: Penata (Gol. III/c) | C14: Lektor
A15: III/d | B15: Penata Tk.I (Gol. III/d)
A16: IV/a | B16: Pembina (Gol. IV/a) | C16: Lektor Kepala
A17: IV/b | B17: Pembina Tk.I (Gol. IV/b)
A18: IV/c | B18: Pembina Utama Muda (Gol. IV/c)
A19: IV/d | B19: Pembina Utama Madya (Gol. IV/d) | C19: Guru Besar
A20: IV/e | B20: Pembina Utama (Gol. IV/e)
